2022-03-16 12:10:45,951 ERROR [/Users/guoshanshangxi/Desktop/python/sample/ClassBasedView/class_based_view/class_based_view/middleware.py:15] この名前は使用できません
Traceback (most recent call last):
  File "/Users/guoshanshangxi/opt/anaconda3/envs/djangoenv/lib/python3.9/site-packages/django/core/handlers/base.py", line 179, in _get_response
    response = wrapped_callback(request, *callback_args, **callback_kwargs)
  File "/Users/guoshanshangxi/opt/anaconda3/envs/djangoenv/lib/python3.9/site-packages/django/views/generic/base.py", line 70, in view
    return self.dispatch(request, *args, **kwargs)
  File "/Users/guoshanshangxi/opt/anaconda3/envs/djangoenv/lib/python3.9/site-packages/django/views/generic/base.py", line 98, in dispatch
    return handler(request, *args, **kwargs)
  File "/Users/guoshanshangxi/opt/anaconda3/envs/djangoenv/lib/python3.9/site-packages/django/views/generic/base.py", line 159, in get
    context = self.get_context_data(**kwargs)
  File "/Users/guoshanshangxi/Desktop/python/sample/ClassBasedView/class_based_view/store/views.py", line 48, in get_context_data
    raise Http404('この名前は使用できません')
django.http.response.Http404: この名前は使用できません
